Workbook

Sheet matutino y especial
A1: REGISTRO DIARIO DE INCIDENCIAS
A2: PERIODO ENERO-ABRIL 2026
A3: TURNOS: MAT Y MAT ESP | D3: =FECHAS!D8 -> LUNES 09 DE FEBRERO DEL 2026 | G3: =FECHAS!G8 -> SEM 6 LIC
A4: ='concentrado diur.'!A4:A5 -> Aula | B4: ='concentrado diur.'!B4:B5 -> Gpo. | C4: ='concentrado diur.'!C4:C5 -> Licenciatura | D4: Op | E4: 7:00 | F4: 8:00 | G4: 9:00 | H4: 10:00 | I4: ='concentrado diur.'!I5 -> 11:00
A5: ='concentrado diur.'!A6 -> CC1 | B5: ='concentrado diur.'!B6 -> 801-9 | C5: ='concentrado diur.'!C6 -> COMPUTACION | D5: ='concentrado diur.'!D6 -> 0 | E5: ='concentrado diur.'!E6 -> 1035 | F5: ='concentrado diur.'!F6 -> 1035 | G5: ='concentrado diur.'!G6 -> A144 | H5: ='concentrado diur.'!H6 -> A144 | I5: ='concentrado diur.'!I6 -> 0
A6: ='concentrado diur.'!A7 -> CC2 | B6: ='concentrado diur.'!B7 -> 501-9 | C6: ='concentrado diur.'!C7 -> COMPUTACION | D6: ='concentrado diur.'!D7 -> 0 | E6: ='concentrado diur.'!E7 -> A161 | F6: ='concentrado diur.'!F7 -> 436 | G6: ='concentrado diur.'!G7 -> 436 | H6: ='concentrado diur.'!H7 -> 2453 | I6: ='concentrado diur.'!I7 -> 2453
A7: ='concentrado diur.'!A8 -> CC3 | B7: ='concentrado diur.'!B8 -> 0 | C7: ='concentrado diur.'!C8 -> 0 | D7: ='concentrado diur.'!D8 -> 0 | E7: ='concentrado diur.'!E8 -> 1094 | F7: ='concentrado diur.'!F8 -> 1094 | G7: ='concentrado diur.'!G8 -> 1228 | H7: ='concentrado diur.'!H8 -> A238 | I7: ='concentrado diur.'!I8 -> 0
A8: ='concentrado diur.'!A9 -> CC4 | B8: ='concentrado diur.'!B9 -> 0 | C8: ='concentrado diur.'!C9 -> 0 | D8: ='concentrado diur.'!D9 -> 0 | E8: ='concentrado diur.'!E9 -> 2130 | F8: ='concentrado diur.'!F9 -> A229 | G8: ='concentrado diur.'!G9 -> A229 CC | H8: ='concentrado diur.'!H9 -> 2353 | I8: ='concentrado diur.'!I9 -> 0
A9: ='concentrado diur.'!A10 -> CC5 | B9: ='concentrado diur.'!B10 -> 0 | C9: ='concentrado diur.'!C10 -> 0 | D9: ='concentrado diur.'!D10 -> 0 | E9: ='concentrado diur.'!E10 -> 1581 | F9: ='concentrado diur.'!F10 -> A144 | G9: ='concentrado diur.'!G10 -> 0 | H9: ='concentrado diur.'!H10 -> 0 | I9: ='concentrado diur.'!I10 -> 0
A10: ='concentrado diur.'!A11 -> 1 | B10: ='concentrado diur.'!B11 -> 603 EAH | C10: ='concentrado diur.'!C11 -> SEMESTRAL | D10: ='concentrado diur.'!D11 -> 0 | E10: ='concentrado diur.'!E11 -> AP27 | F10: ='concentrado diur.'!F11 -> AP27 | G10: ='concentrado diur.'!G11 -> P274 | H10: ='concentrado diur.'!H11 -> P274 | I10: ='concentrado diur.'!I11 -> P433
A11: ='concentrado diur.'!A12 -> 2 | B11: ='concentrado diur.'!B12 -> 701-13/801-14/ 101-13 ic | C11: ='concentrado diur.'!C12 -> PSICOLOGIA | D11: ='concentrado diur.'!D12 -> 5BM Y 5DM, 11GD | E11: ='concentrado diur.'!E12 -> A139 | F11: ='concentrado diur.'!F12 -> A139 | G11: ='concentrado diur.'!G12 -> 2517 | H11: ='concentrado diur.'!H12 -> 0 | I11: ='concentrado diur.'!I12 -> 0
A12: ='concentrado diur.'!A13 -> 3 | B12: ='concentrado diur.'!B13 -> 1001-13/1101-14/211-9 | C12: ='concentrado diur.'!C13 -> PSICOLOGIA | D12: ='concentrado diur.'!D13 -> 11AM | E12: ='concentrado diur.'!E13 -> A231 | F12: ='concentrado diur.'!F13 -> A231 | G12: ='concentrado diur.'!G13 -> 2124 | H12: ='concentrado diur.'!H13 -> 2353 CC | I12: ='concentrado diur.'!I13 -> 2353
A13: ='concentrado diur.'!A14 -> 4 | B13: ='concentrado diur.'!B14 -> 501-11 | C13: ='concentrado diur.'!C14 -> ELECTRO | D13: ='concentrado diur.'!D14 -> 0 | E13: ='concentrado diur.'!E14 -> 1534 | F13: ='concentrado diur.'!F14 -> 1534 | G13: ='concentrado diur.'!G14 -> 2314 | H13: ='concentrado diur.'!H14 -> 2314 | I13: ='concentrado diur.'!I14 -> 2154
A14: ='concentrado diur.'!A15 -> 5 | B14: ='concentrado diur.'!B15 -> 401-8/501-9 | C14: ='concentrado diur.'!C15 -> CIVIL | D14: ='concentrado diur.'!D15 -> 5AD | E14: ='concentrado diur.'!E15 -> 2401 | F14: ='concentrado diur.'!F15 -> A169 | G14: ='concentrado diur.'!G15 -> A169 | H14: ='concentrado diur.'!H15 -> 1152 | I14: ='concentrado diur.'!I15 -> 1152
A15: ='concentrado diur.'!A16 -> 7 | B15: ='concentrado diur.'!B16 -> 401-8/501-9 | C15: ='concentrado diur.'!C16 -> NEGOCIOS | D15: ='concentrado diur.'!D16 -> 0 | E15: ='concentrado diur.'!E16 -> A198 | F15: ='concentrado diur.'!F16 -> 2472 | G15: ='concentrado diur.'!G16 -> A191 | H15: ='concentrado diur.'!H16 -> 1433 | I15: ='concentrado diur.'!I16 -> 1433
A16: ='concentrado diur.'!A17 -> 8 | B16: ='concentrado diur.'!B17 -> 501-9/511-9 | C16: ='concentrado diur.'!C17 -> PSICOLOGIA | D16: ='concentrado diur.'!D17 -> 5BD | E16: ='concentrado diur.'!E17 -> 0 | F16: ='concentrado diur.'!F17 -> 2521 | G16: ='concentrado diur.'!G17 -> A231 | H16: ='concentrado diur.'!H17 -> 382 | I16: ='concentrado diur.'!I17 -> 2166
... A21: ='concentrado diur.'!A22 -> 104 | B21: ='concentrado diur.'!B22 -> 403 | C21: ='concentrado diur.'!C22 -> SEMESTRAL | D21: ='concentrado diur.'!D22 -> 0 | E21: ='concentrado diur.'!E22 -> 0 | F21: ='concentrado diur.'!F22 -> P463 | G21: ='concentrado diur.'!G22 -> P463 | H21: ='concentrado diur.'!H22 -> P453 | I21: ='concentrado diur.'!I22 -> P453
A23: =A1 -> REGISTRO DIARIO DE INCIDENCIAS
A24: =A2 -> PERIODO ENERO-ABRIL 2026
A25: TURNOS: MAT Y MAT ESP | D25: =D3 -> LUNES 09 DE FEBRERO DEL 2026 | G25: =G3 -> SEM 6 LIC
A26: =A4 -> Aula | B26: =B4 -> Gpo. | C26: =C4 -> Licenciatura | D26: =D4 -> Op | E26: =E4 -> 7:00 | F26: =F4 -> 8:00 | G26: =G4 -> 9:00 | H26: =H4 -> 10:00 | I26: =I4 -> 11:00
A27: ='concentrado diur.'!A23 -> 201 | B27: ='concentrado diur.'!B23 -> 701-8/801-9 | C27: ='concentrado diur.'!C23 -> INDUSTRIAL | D27: ='concentrado diur.'!D23 -> 8DB | E27: ='concentrado diur.'!E23 -> 1562 | F27: ='concentrado diur.'!F23 -> 1562 | G27: ='concentrado diur.'!G23 -> 2453 | H27: ='concentrado diur.'!H23 -> A184 | I27: ='concentrado diur.'!I23 -> A184
A28: ='concentrado diur.'!A24 -> 202 | B28: ='concentrado diur.'!B24 -> 1301-13/1401-14 | C28: ='concentrado diur.'!C24 -> NEGOCIOS | D28: ='concentrado diur.'!D24 -> 0 | E28: ='concentrado diur.'!E24 -> 1357 | F28: ='concentrado diur.'!F24 -> A55 | G28: ='concentrado diur.'!G24 -> 1060 | H28: ='concentrado diur.'!H24 -> 0 | I28: ='concentrado diur.'!I24 -> 0
A29: ='concentrado diur.'!A25 -> sim | B29: ='concentrado diur.'!B25 -> 0 | C29: ='concentrado diur.'!C25 -> 0 | D29: ='concentrado diur.'!D25 -> 0 | E29: ='concentrado diur.'!E25 -> 0 | F29: ='concentrado diur.'!F25 -> 0 | G29: ='concentrado diur.'!G25 -> 0 | H29: ='concentrado diur.'!H25 -> 0 | I29: ='concentrado diur.'!I25 -> 0
A30: ='concentrado diur.'!A26 -> 204 | B30: ='concentrado diur.'!B26 -> 101-8 | C30: ='concentrado diur.'!C26 -> CIVIL | D30: ='concentrado diur.'!D26 -> 0 | E30: ='concentrado diur.'!E26 -> 2338 | F30: ='concentrado diur.'!F26 -> 2338 | G30: ='concentrado diur.'!G26 -> S 207 | H30: ='concentrado diur.'!H26 -> S 313 | I30: ='concentrado diur.'!I26 -> S 313
A31: ='concentrado diur.'!A27 -> 205 | B31: ='concentrado diur.'!B27 -> 401-13/501-14 | C31: ='concentrado diur.'!C27 -> PSICOLOGIA | D31: ='concentrado diur.'!D27 -> 2AM, 8CD, 8FD | E31: ='concentrado diur.'!E27 -> 1303 | F31: ='concentrado diur.'!F27 -> 1303 | G31: ='concentrado diur.'!G27 -> A139 | H31: ='concentrado diur.'!H27 -> 0 | I31: ='concentrado diur.'!I27 -> 0
A32: ='concentrado diur.'!A28 -> 206 | B32: ='concentrado diur.'!B28 -> 1001-13/1101-14 | C32: ='concentrado diur.'!C28 -> CIVIL | D32: ='concentrado diur.'!D28 -> 8BM | E32: ='concentrado diur.'!E28 -> A183 | F32: ='concentrado diur.'!F28 -> A261 | G32: ='concentrado diur.'!G28 -> A261 | H32: ='concentrado diur.'!H28 -> 0 | I32: ='concentrado diur.'!I28 -> 0
A33: ='concentrado diur.'!A29 -> 206 | B33: ='concentrado diur.'!B29 -> 0 | C33: ='concentrado diur.'!C29 -> 0 | D33: ='concentrado diur.'!D29 -> 8CM | E33: ='concentrado diur.'!E29 -> 0 | F33: ='concentrado diur.'!F29 -> 0 | G33: ='concentrado diur.'!G29 -> 0 | H33: ='concentrado diur.'!H29 -> 0 | I33: ='concentrado diur.'!I29 -> 0
A34: ='concentrado diur.'!A30 -> 207 | B34: ='concentrado diur.'!B30 -> 201-14 | C34: ='concentrado diur.'!C30 -> PSICOLOGIA | D34: ='concentrado diur.'!D30 -> 2DD, 8ED | E34: ='concentrado diur.'!E30 -> 2325 | F34: ='concentrado diur.'!F30 -> 1581 | G34: ='concentrado diur.'!G30 -> 382 | H34: ='concentrado diur.'!H30 -> 0 | I34: ='concentrado diur.'!I30 -> 0
A35: ='concentrado diur.'!A31 -> 208 | B35: ='concentrado diur.'!B31 -> 801-14 | C35: ='concentrado diur.'!C31 -> CIVIL | D35: ='concentrado diur.'!D31 -> 5DM | E35: ='concentrado diur.'!E31 -> A77 | F35: ='concentrado diur.'!F31 -> 1152 | G35: ='concentrado diur.'!G31 -> 1152 | H35: ='concentrado diur.'!H31 -> 0 | I35: ='concentrado diur.'!I31 -> 0
A36: ='concentrado diur.'!A32 -> 209 | B36: ='concentrado diur.'!B32 -> 501-14 | C36: ='concentrado diur.'!C32 -> CIVIL | D36: ='concentrado diur.'!D32 -> 0 | E36: ='concentrado diur.'!E32 -> A169 | F36: ='concentrado diur.'!F32 -> A183 | G36: ='concentrado diur.'!G32 -> 2306 | H36: ='concentrado diur.'!H32 -> 0 | I36: ='concentrado diur.'!I32 -> 0
A37: ='concentrado diur.'!A33 -> 210 | B37: ='concentrado diur.'!B33 -> 401-8/101-8 IIA | C37: ='concentrado diur.'!C33 -> CIVIL | D37: ='concentrado diur.'!D33 -> 0 | E37: ='concentrado diur.'!E33 -> 2182 IIA 2503 S 209 | F37: ='concentrado diur.'!F33 -> 1517 | G37: ='concentrado diur.'!G33 -> 1517 | H37: ='concentrado diur.'!H33 -> S 309-A | I37: ='concentrado diur.'!I33 -> S 309-A
A38: ='concentrado diur.'!A34 -> 211 | B38: ='concentrado diur.'!B34 -> 201-9 | C38: ='concentrado diur.'!C34 -> NEGOCIOS | D38: ='concentrado diur.'!D34 -> 8BD | E38: ='concentrado diur.'!E34 -> 2448 | F38: ='concentrado diur.'!F34 -> 2448 | G38: ='concentrado diur.'!G34 -> 992 | H38: ='concentrado diur.'!H34 -> 992 | I38: ='concentrado diur.'!I34 -> 992
... A52: ='concentrado diur.'!A48 -> 221 | B52: ='concentrado diur.'!B48 -> 201-9 | C52: ='concentrado diur.'!C48 -> INDUSTRIAL | D52: ='concentrado diur.'!D48 -> 0 | E52: ='concentrado diur.'!E48 -> A164 | F52: ='concentrado diur.'!F48 -> A164 | G52: ='concentrado diur.'!G48 -> 1581 | H52: ='concentrado diur.'!H48 -> A89 | I52: ='concentrado diur.'!I48 -> 1633
A54: =A23 -> REGISTRO DIARIO DE INCIDENCIAS
A55: =A24 -> PERIODO ENERO-ABRIL 2026
A56: TURNOS: MAT Y MAT ESP | D56: =D25 -> LUNES 09 DE FEBRERO DEL 2026 | G56: =G25 -> SEM 6 LIC
A57: =A26 -> Aula | B57: =B26 -> Gpo. | C57: =C26 -> Licenciatura | D57: =D26 -> Op | E57: =E26 -> 7:00 | F57: =F26 -> 8:00 | G57: =G26 -> 9:00 | H57: =H26 -> 10:00 | I57: =I26 -> 11:00
A58: ='concentrado diur.'!A49 -> 301 | B58: ='concentrado diur.'!B49 -> 601 FMQB | C58: ='concentrado diur.'!C49 -> SEMESTRAL | D58: ='concentrado diur.'!D49 -> 0 | E58: ='concentrado diur.'!E49 -> AP35 | F58: ='concentrado diur.'!F49 -> P453 | G58: ='concentrado diur.'!G49 -> AP4 | H58: ='concentrado diur.'!H49 -> P456 | I58: ='concentrado diur.'!I49 -> AP8
A59: ='concentrado diur.'!A50 -> 301-A | B59: ='concentrado diur.'!B50 -> 1301-13/1401-14 | C59: ='concentrado diur.'!C50 -> CIVIL | D59: ='concentrado diur.'!D50 -> 0 | E59: ='concentrado diur.'!E50 -> 1887 | F59: ='concentrado diur.'!F50 -> 1887 | G59: ='concentrado diur.'!G50 -> A43 | H59: ='concentrado diur.'!H50 -> 0 | I59: ='concentrado diur.'!I50 -> 0
...

Sheet concentrado diur.
A1: Concentrado General De Catedráticos Y Grupos.
A2: PERIODO ENERO-ABBRIL 2026
A3: MATUTINO 2026
A4: Aula | B4: Gpo. | C4: Licenciatura | D4: Opt | E4: Lunes | J4: Martes | O4: Miércoles | T4: Jueves | Y4: Viernes | AD4: Aula
E5: 7:00 | F5: 8:00 | G5: 9:00 | H5: 10:00 | I5: 11:00 | J5: 7:00 | K5: 8:00 | L5: 9:00 | M5: 10:00 | N5: 11:00 | O5: 7:00 | P5: 8:00 | Q5: 9:00 | R5: 10:00 | S5: 11:00 | T5: 7:00 | U5: 8:00 | V5: 9:00 | W5: 10:00 | X5: 11:00 | Y5: 7:00 | Z5: 8:00 | AA5: 9:00 | AB5: 10:00 | AC5: 11:00
A6: CC1 | B6: 801-9 | C6: COMPUTACION | E6: 1035 | F6: 1035 | G6: A144 | H6: A144 | J6: 436 | K6: 436 | L6: A38 SIM | O6: 1035 | P6: 2040 211 | Q6: 2040 209 | R6: A38 SIM | S6: A38 SIM | T6: A229 | U6: A229 | V6: A144 | Y6: 436 | Z6: 436 | AA6: A229 | AB6: 1517 | AC6: 1517 | AD6: =A6 -> CC1
A7: CC2 | B7: 501-9 | C7: COMPUTACION | E7: A161 | F7: 436 | G7: 436 | H7: 2453 | I7: 2453 | J7: A161 | K7: 2503 SIM | L7: 2453 | M7: A38 SIM | N7: A38 SIM | O7: A161 | P7: 2503 SIM | Q7: A38 SIM | R7: 1228 | T7: 335 | U7: 335 | V7: 2503 SIM | W7: 1567 S. 309A | X7: 1246 S 309-A | Y7: 335 | Z7: 335 | AA7: 436 | AC7: 1228 | AD7: =A7 -> CC2
A8: CC3 | E8: 1094 | F8: 1094 | G8: 1228 | H8: A238 | J8: 1228 201-14 NI | K8: 1228 NI 201-14 | L8: 1228 | O8: 634 | P8: 1094 | Q8: A144 | R8: A144 | S8: 1517 | T8: 1228 | U8: A97 | V8: A229 | Y8: 1228 | Z8: 2130 | AA8: A144 | AC8: A238 | AD8: =A8 -> CC3
A9: CC4 | E9: 2130 | F9: A229 | G9: A229 CC | H9: 2353 | J9: 2130 | K9: 335 | L9: 335 | O9: 1228 | P9: 1228 | S9: A144 | T9: 2130 | U9: 2130 | V9: 335 | Y9: 2101 | Z9: 2101 | AA9: 1228 | AD9: =A9 -> CC4
A10: CC5 | E10: 1581 | F10: A144 | J10: 634 201-14 ico | K10: 634 (201-14 ico) | O10: 2130 | P10: 2130 | T10: 1581 | U10: 1581 | V10: 1228 | Y10: 2130 | Z10: A229 | AD10: =A10 -> CC5
A11: 1 | B11: 603 EAH | C11: SEMESTRAL | E11: AP27 | F11: AP27 | G11: P274 | H11: P274 | I11: P433 | J11: P398 | K11: AP20 | L11: AP20 | M11: P274 | N11: P456 | O11: AP22 | P11: P294 | Q11: AP20 | R11: AP4 | S11: P274 | T11: P294 | U11: P466 | V11: P398 | W11: AP8 | X11: P433 | Y11: P294 | Z11: P398 | AA11: AP8 | AB11: AP8 | AC11: AP17 | AD11: =A11 -> 1
A12: 2 | B12: 701-13/801-14/ 101-13 ic | C12: PSICOLOGIA | D12: 5BM Y 5DM, 11GD | E12: A139 | F12: A139 | G12: 2517 | J12: 2166 | K12: 2517 | L12: 2521 | M12: 1435 | N12: 1435 | O12: 1836 | P12: A133 | Q12: A133 | T12: 2521 | U12: 2521 | V12: 2517 | W12: 1435 | X12: 1435 | Y12: 2166 | Z12: A133 | AA12: A133 | AD12: =A12 -> 2
A13: 3 | B13: 1001-13/1101-14/211-9 | C13: PSICOLOGIA | D13: 11AM | E13: A231 | F13: A231 | G13: 2124 | H13: 2353 CC | I13: 2353 | J13: A121 | K13: A133 | L13: A133 | M13: A77 | N13: A77 | O13: 2124 | P13: 2124 | Q13: 1456 | R13: S 315 | S13: 2023 | T13: 1456 | U13: A133 | V13: A133 | W13: 2231 | X13: 2231 | Y13: A121 | Z13: 1456 | AA13: 1633 | AB13: 2372 | AC13: 2372 | AD13: =A13 -> 3
A14: 4 | B14: 501-11 | C14: ELECTRO | E14: 1534 | F14: 1534 | G14: 2314 | H14: 2314 | I14: 2154 | J14: 1662 | K14: 1662 | L14: 2314 | M14: 2154 | N14: 1567 | O14: 1534 | P14: 1534 | Q14: 2154 | R14: A77 | S14: A77 | T14: 1662 | U14: 1662 | V14: 1662 | W14: 2314 | Y14: 1534 | Z14: 1534 | AA14: 2154 | AD14: =A14 -> 4
A15: 5 | B15: 401-8/501-9 | C15: CIVIL | D15: 5AD | E15: 2401 | F15: A169 | G15: A169 | H15: 1152 | I15: 1152 | J15: 2353 | K15: A169 | L15: 1384 | M15: 2401 | N15: 1887 | O15: A260 | P15: A260 | Q15: A77 | R15: 1846 | S15: 1846 | T15: A260 | U15: 1152 | V15: A77 | W15: 1384 | X15: 1887 | Y15: 1887 | Z15: 1887 | AA15: A77 | AB15: 1846 | AC15: 1846 | AD15: =A15 -> 5
A16: 7 | B16: 401-8/501-9 | C16: NEGOCIOS | E16: A198 | F16: 2472 | G16: A191 | H16: 1433 | I16: 1433 | J16: A198 | K16: 1836 | L16: 2353 | M16: 2040 | N16: 2040 | O16: A234 | P16: A234 | Q16: 1433 | T16: A198 | U16: 2472 | V16: 1433 | W16: 2040 | X16: 2040 | Y16: 2472 | Z16: A191 | AA16: A191 | AD16: =A16 -> 7
A17: 8 | B17: 501-9/511-9 | C17: PSICOLOGIA | D17: 5BD | F17: 2521 | G17: A231 | H17: 382 | I17: 2166 | J17: 2531 | K17: 2521 | L17: A231 | M17: A231 | N17: 2166 | O17: 2531 | P17: 1456 | Q17: 1524 | R17: 1433 | S17: 1433 | U17: 1456 | V17: 1524 | W17: 2353 | X17: A185 | Y17: 1456 | Z17: 2531 | AA17: 1524 | AB17: 1433 | AC17: 1433 | AD17: =A17 -> 8
A18: 9 | B18: 501-9 | C18: MECATRONICA | D18: 2CM, 5CD | E18: 1094 CC | F18: 1094 CC | G18: A163 | H18: A163 | I18: 2179 | J18: 2453 | K18: 2453 | L18: 2040 | M18: 2388 | N18: 2179 | O18: 1633 | P18: 1094 CC 2395 | Q18: A163 CC 2395 | R18: A133 | S18: A133 | T18: 2154 | U18: 2154 | V18: 2040 | W18: 2179 | X18: 2179 | Y18: 2388 | Z18: 2388 (2395) | AA18: 1567 (2395) | AB18: A133 | AC18: A133 | AD18: =A18 -> 9
A19: 101 | B19: 201-9 | C19: CIVIL | D19: 2CD | E19: 1517 | F19: 848 | G19: 2338 | H19: 2074 | I19: 2074 | J19: 245 | K19: 848 | L19: 2338 | M19: A160 | N19: A160 | O19: 848 | P19: 848 | Q19: 2338 | R19: 1633 | S19: 1517 CC | T19: 245 | U19: 245 | V19: 2338 | W19: A160 | X19: A160 | Y19: 848 | Z19: 1517 | AA19: 1517 | AB19: 2074 | AC19: 1567 | AD19: =A19 -> 101
A20: 102 | B20: 201-14 | C20: CIVIL | D20: 11FD, 5DD | E20: 848 | F20: 2074 | G20: 2074 | J20: 848 | K20: 1517 | L20: 1517 | M20: A133 | N20: A133 | O20: 245 | P20: 245 | Q20: 1633 | R20: 2476 | S20: 2476 | T20: 2338 | U20: 1517 | V20: 1517 | W20: A133 | X20: A133 | Y20: 2338 | Z20: 848 | AA20: 2074 | AB20: 2476 | AC20: 2476 | AD20: =A20 -> 102
A21: 103 | B21: 701-8/801-9 | C21: CIVIL | D21: 8AD | E21: A261 | F21: 2306 | G21: 1384 | H21: 1384 | I21: 2401 | J21: 1887 | K21: 1887 | L21: 1152 | M21: 2476 | N21: 2476 | O21: A261 | P21: A261 | Q21: 1076 | R21: 1076 | S21: 1887 | T21: A145 | U21: 2306 | V21: 2306 | W21: 2476 | X21: 2476 | Y21: A43 | Z21: A43 | AA21: 1384 | AB21: 1152 | AC21: A145 | AD21: =A21 -> 103
A22: 104 | B22: 403 | C22: SEMESTRAL | F22: P463 | G22: P463 | H22: P453 | I22: P453 | J22: P463 | K22: P463 | L22: P398 | M22: AP4 | N22: P274 | P22: P398 | Q22: P453 | R22: P463 | S22: AP37 | T22: AP20 | U22: AP20 | V22: P453 | W22: AP4 | X22: P453 | Y22: AP20 | Z22: P449 | AA22: P449 | AB22: AP37 | AC22: P398 | AD22: =A22 -> 104
A23: 201 | B23: 701-8/801-9 | C23: INDUSTRIAL | D23: 8DB | E23: 1562 | F23: 1562 | G23: 2453 | H23: A184 | I23: A184 | J23: A89 | K23: A89 | L23: 2182 | M23: A250 | N23: A250 | O23: 1562 | P23: 2182 | Q23: 2453 | R23: A184 | S23: 1246 | T23: A89 | U23: A89 | V23: 2182 | W23: A250 | X23: A250 | Y23: 1562 | Z23: 1562 | AA23: 2182 | AB23: A184 | AC23: A184 | AD23: =A23 -> 201
A24: 202 | B24: 1301-13/1401-14 | C24: NEGOCIOS | E24: 1357 | F24: A55 | G24: 1060 | J24: A55 | K24: 2472 | L24: 1060 | O24: 1303 | P24: 2472 | Q24: 1357 | T24: 2472 | U24: 1357 | V24: A55 | Y24: 1303 | Z24: 2472 | AA24: A55 | AD24: =A24 -> 202
A25: sim | K25: 2503 | L25: A38 | M25: A38 | N25: A38 | O25: 634 201-14 ico | P25: 2503 | Q25: A38 | R25: A38 | S25: A38 | T25: 2353 NI | U25: 2353 NI | V25: 2503 | Y25: 1517 | Z25: 2448 | AA25: 2448 | AD25: =A25 -> sim
A26: 204 | B26: 101-8 | C26: CIVIL | E26: 2338 | F26: 2338 | G26: S 207 | H26: S 313 | I26: S 313 | J26: 2401 | K26: A183 | L26: 2231 | O26: A183 | P26: 2338 | Q26: 2231 | R26: 2231 | S26: 2231 | T26: A171 | U26: A171 | V26: A171 | Z26: 2338 | AA26: A171 | AB26: S 309-A | AC26: 309-A | AD26: =A26 -> 204
A27: 205 | B27: 401-13/501-14 | C27: PSICOLOGIA | D27: 2AM, 8CD, 8FD | E27: 1303 | F27: 1303 | G27: A139 | J27: 1633 | K27: 2395 | L27: 2395 | M27: A140 | N27: A140 | O27: A139 | P27: 2531 | Q27: 2531 | R27: 2395 | S27: 2395 | T27: A139 | U27: 2395 | V27: 2395 | W27: A140 | X27: A140 | Y27: A139 | Z27: 1303 | AA27: 2531 | AB27: 2395 | AC27: 2395 | AD27: =A27 -> 205
A28: 206 | B28: 1001-13/1101-14 | C28: CIVIL | D28: 8BM | E28: A183 | F28: A261 | G28: A261 | J28: A183 | K28: 1435 | L28: 1435 | O28: A200 | P28: A200 | Q28: A261 | T28: 2306 | U28: 1435 | V28: 1435 | Y28: S 219 | Z28: 2306 | AA28: 2306 | AD28: =A28 -> 206
A29: 206 | D29: 8CM | AD29: =A29 -> 206
A30: 207 | B30: 201-14 | C30: PSICOLOGIA | D30: 2DD, 8ED | E30: 2325 | F30: 1581 | G30: 382 | J30: A139 | K30: A139 | L30: 2473 | M30: 2451 | N30: 2451 | O30: 2325 | P30: 1581 | Q30: 2473 | R30: 1435 | S30: 1435 | T30: 2325 | U30: A139 | V30: 1581 | W30: 2451 | X30: 2451 | Y30: 2325 | Z30: 2517 | AA30: 2517 | AB30: 1435 | AC30: 1435 | AD30: =A30 -> 207
A31: 208 | B31: 801-14 | C31: CIVIL | D31: 5DM | E31: A77 | F31: 1152 | G31: 1152 | J31: A77 | K31: A77 | L31: S 211 | O31: 2401 | P31: 1435 | Q31: 1435 | T31: 1384 | U31: 1384 | V31: 1152 | Y31: 2401 | Z31: 1435 | AA31: 1435 | AD31: =A31 -> 208
A32: 209 | B32: 501-14 | C32: CIVIL | E32: A169 | F32: A183 | G32: 2306 | J32: A169 | K32: 2467 | L32: 2467 | O32: 2306 | P32: 2306 | Q32: 2353 | T32: A169 | U32: 2467 | V32: 2467 | Y32: 2306 | Z32: A183 | AA32: A183 | AD32: =A32 -> 209
A33: 210 | B33: 401-8/101-8 IIA | C33: CIVIL | E33: 2182 IIA 2503 S 209 | F33: 1517 | G33: 1517 | H33: S 309-A | I33: S 309-A | J33: A95 | K33: A95 | L33: A95 | M33: 2231 | N33: 2231 | O33: 1517 | P33: 1517 | Q33: 1512 | R33: 1153 | S33: 1153 | T33: 1512 | U33: 1512 | V33: A95 | X33: 2306 | Y33: 2182 IIA 2503 S 215 | Z33: 1153 IIA 2503 S 215 | AA33: 1153 | AB33: S 309-A | AC33: 309-A | AD33: =A33 -> 210
A34: 211 | B34: 201-9 | C34: NEGOCIOS | D34: 8BD | E34: 2448 | F34: 2448 | G34: 992 | H34: 992 | I34: 992 | J34: 2023 | K34: 2023 | L34: 1228 CC 1567 | M34: A122 | N34: A122 | O34: 1228 CC | P34: 1228 CC | Q34: A96 | R34: 1246 | S34: 382 | T34: 2448 | U34: 1782 | V34: 1782 | W34: A122 | X34: A122 | Y34: 2448 | Z34: 1782 | AA34: 1782 | AB34: A96 | AC34: A96 | AD34: =A34 -> 211
A35: 212 | B35: 201-14 | C35: ELECTRO | E35: 2314 | F35: 2314 | J35: 1534 | K35: 335 cc | L35: 335 CC 1782 NI | M35: 992 NI | N35: 992 NI | O35: 1865 | P35: 1865 | Q35: 1836 | T35: 1534 | U35: 1534 | V35: 335 CC | Y35: 2314 | Z35: 2314 | AA35: 2314 | AD35: =A35 -> 212
A36: 213 | B36: 801-14 | C36: NEGOCIOS | E36: 2472 | F36: 1357 | G36: 1357 | J36: 2472 | K36: 2166 | L36: 1567 S 211 | O36: 2472 | T36: 2166 | U36: 2166 | V36: 1357 | Y36: 1357 | AD36: =A36 -> 213 | BJ36: <
A37: 214 | B37: 801-14 | C37: INDUSTRIAL | E37: 964 | F37: A89 | G37: A89 | J37: 2525 | K37: 2525 | L37: 964 | O37: A89 | T37: 964 | U37: 2525 | V37: 2525 | Y37: S 308 | AD37: =A37 -> 214
A38: 215 | B38: 1401-14 | C38: PSICOLOGIA | E38: 2124 | F38: 2124 | G38: A185 | J38: 2124 | K38: 2326 | L38: A185 | O38: 1456 | P38: 2326 | Q38: A185 | T38: 2326 | U38: 2326 | V38: 1456 | Y38: S 301-A | Z38: S 301-A | AA38: A185 | AD38: =A38 -> 215
A39: 216 | B39: 1301-13/1401-14 | C39: ELECTRO | E39: 2101 | F39: 2101 | G39: S 202 | J39: 2101 | K39: 2101 | L39: S 202 | O39: 2353 | P39: 2179 | Q39: 2179 | T39: 1865 | U39: 1865 | V39: 2179 | Y39: A79 | Z39: 1865 | AA39: 2179 | AD39: =A39 -> 216
A40: 217 | B40: 801-14 | C40: FINANZAS | E40: A99 | F40: A114 | G40: A99 | J40: A238 | K40: A238 | L40: A238 | M40: 436 | N40: 436 | O40: A99 | T40: A99 | U40: A114 | V40: A114 | W40: 436 | X40: 436 | Y40: S 308 | AD40: =A40 -> 217
...

Sheet FECHAS
D8: LUNES 09 DE FEBRERO DEL 2026 | G8: SEM 6 LIC | H8: SEM 4 VAC
D9: MARTES 10 DE FEBRERO DEL 2026
D10: MIERCOLES 11 DE FEBRERO DEL 2026
D11: JUEVES 12 DE FEBRERO DEL 2026
D12: VIERNES 13 DE FEBRERO DEL 2026

Sheet Hoja4
