Workbook

Sheet diur2
A1: Concentrado General De Catedráticos Y Grupos.
A2: PERIODO ENERO-ABRIL 2026
A3: MATUTINO 2026
A4: Aula | B4: Gpo. | C4: Licenciatura | D4: Opt | E4: Lunes | H4: Martes | K4: Miércoles | N4: Jueves | Q4: Viernes | T4: Aula
E5: 12:00 | F5: 13:00 | G5: 14:00 | H5: 12:00 | I5: 13:00 | J5: 14:00 | K5: 12:00 | L5: 13:00 | M5: 14:00 | N5: 12:00 | O5: 13:00 | P5: 14:00 | Q5: 12:00 | R5: 13:00 | S5: 14:00
A6: 004 | B6: 601-8 | C6: NEGOCIOS | E6: 2166 | K6: 2166 | T6: =A6 -> 004
A7: 007 | B7: 501-8 | C7: NEGOCIOS | E7: 1246 | H7: 2166 | K7: 1228 | N7: 1246 | T7: =A7 -> 007
A8: 102 | B8: 201-8 | C8: CIVIL | E8: 1246 | H8: 2231 | K8: 2074 | N8: 2074 | Q8: 2074 | T8: =A8 -> 102
A9: 104 | B9: 303 | C9: SEMESTRAL | E9: P453 | F9: P453 | H9: AP5 | I9: P274 | K9: P274 | L9: P274 | N9: AP27 | O9: P449 | Q9: P449 | R9: P449 | T9: =A9 -> 104
A10: 207 | B10: 411-9 | C10: PSICOLOGIA | E10: 2422 | F10: 2409 | H10: 2326 | I10: 2531 | K10: 2409 | L10: 2409 | N10: 2531 | Q10: 2326 | R10: 2531 | T10: =A10 -> 207
A11: 204 | B11: 111-9 | C11: PSICOLOGIA | E11: 2023 | F11: 1060 | G11: 1228 | H11: 2531 | I11: 2422 | J11: 2353 | K11: 2023 | L11: 2531 | M11: 2531 | N11: 2422 | O11: 2353 | P11: 2353 | Q11: 1060 | R11: 1060 | S11: 1228 | T11: =A11 -> 204
A12: 302 | B12: 502 | C12: SEMESTRAL | D12: FMQB | E12: P413 | F12: P413 | H12: P347 | I12: P347 | K12: AP27 | N12: P440 | O12: AP22 | Q12: AP27 | R12: P413 | T12: =A12 -> 302
A13: 303 | B13: 302 | C13: SEMESTRAL | E13: P449 | F13: P449 | H13: AP27 | I13: AP20 | K13: P449 | N13: AP20 | O13: AP20 | Q13: AP20 | T13: =A13 -> 303
A14: 304 | B14: 101 | C14: SEMESTRAL | E14: P452 | F14: P452 | H14: P2396 | I14: AP21 | K14: AP21 | L14: AP21 | N14: P452 | O14: P2396 | Q14: P452 | R14: P452 | T14: =A14 -> 304
A15: 305 | B15: 102 | C15: SEMESTRAL | E15: AP17 | F15: AP21 | H15: AP22 | I15: AP22 | K15: P452 | L15: P452 | N15: P466 | O15: P452 | Q15: AP17 | R15: AP17 | T15: =A15 -> 305
A16: 306 | T16: =A16 -> 306
A17: 301 | B17: 501 | C17: SEMESTRAL | D17: FMQB | E17: P466 | F17: AP20 | H17: A921 | I17: A927 | K17: P413 | L17: P413 | N17: AP5 | O17: AP5 | Q17: P413 | R17: AP8 | T17: =A17 -> 301
A18: 311 | B18: 301 | C18: SEMESTRAL | E18: P274 | F18: P274 | H18: P274 | I18: P453 | K18: P347 | L18: P347 | N18: P449 | Q18: AP21 | T18: =A18 -> 311
A19: 001 | B19: 503 | C19: SEMESTRAL | D19: EAH | E19: AP27 | F19: P347 | H19: AP8 | I19: AP5 | K19: AP17 | L19: AP22 | N19: AP22 | O19: P347 | Q19: AP8 | R19: AP5 | T19: =A19 -> 001
T20: =A20 -> 0
A273: =diur2!#REF! -> #REF!

Sheet bitacora diurno
A1: REGISTRO DIARIO DE INCIDENCIAS
A2: PERIODO ENERO- ABRIL 2026
A3: TURNOS: MAT Y MAT ESP | D3: =FECHAS!D8 -> LUNES 23 DE FEBRERO DEL 2026 | F3: =FECHAS!G8 -> SEM 8 LIC | G3: =FECHAS!H8 -> SEM 2 SEM
A4: =diur2!A4 -> Aula | B4: =diur2!B4 -> Gpo. | C4: =diur2!C4 -> Licenciatura | D4: =diur2!D4 -> Opt | E4: 0.5 | F4: 0.54166667 | G4: 0.58333333
A5: 001 | B5: 603 EAH | C5: SEMESTRAL | E5: P456 | F5: P456 | G5: =diur2!G2 -> 0
A6: 002 | B6: 211-9 | C6: PSICOLOGIA | D6: =diur2!D5 -> 0 | E6: 1246 | F6: 2372 | G6: 2372
A8: =diur2!A6 -> 004 | B8: 401-8 | C8: =diur2!C6 -> NEGOCIOS | E8: 2166 | F8: =diur2!F6 -> 0 | G8: =diur2!G6 -> 0
A9: 008 | B9: 511-9 | C9: PSICOLOGIA | E9: 2372 | F9: =diur2!F7 -> 0 | G9: =diur2!G7 -> 0
A10: 102 | C10: INGLES | F10: =diur2!F8 -> 0 | G10: =diur2!G8 -> 0
A11: =diur2!A9 -> 104 | B11: 202 | C11: =diur2!C9 -> SEMESTRAL | E11: AP17 | F11: AP17 | G11: =diur2!G9 -> 0
A12: 204 | B12: 101-8 | C12: CIVIL | E12: 2401
A13: 206 | B13: 701-8 | C13: CIVIL
A14: 210 | B14: 401-8 | C14: CIVIL | E14: 2306
A15: 301 | B15: 601 FMQB | C15: SEMESTRAL | E15: P466 | F15: AP38
A16: =diur2!A12 -> 302 | B16: 602 FMQB | C16: =diur2!C12 -> SEMESTRAL | E16: P433 | F16: P347
A17: =diur2!A13 -> 303 | B17: 402 | C17: =diur2!C13 -> SEMESTRAL | E17: AP38 | F17: AP22
A18: =diur2!A14 -> 304 | B18: 201 | C18: =diur2!C14 -> SEMESTRAL | E18: P452 | F18: P452
A19: 305 | B19: 403 | C19: SEMESTRAL | E19: P274 | F19: AP8
A20: =diur2!A18 -> 311 | B20: 401 | C20: =diur2!C18 -> SEMESTRAL | E20: AP36 | F20: AP36
A21: 313 | B21: 101-8 | C21: FINANZAS | E21: A238
A22: =diur2!A20 -> 0 | B22: =diur2!B20 -> 0 | C22: =diur2!C20 -> 0 | D22: =diur2!D20 -> 0 | E22: =diur2!E20 -> 0 | F22: =diur2!F20 -> 0 | G22: =diur2!G20 -> 0
A25: =A1 -> REGISTRO DIARIO DE INCIDENCIAS
A26: =A2 -> PERIODO ENERO- ABRIL 2026
A27: TURNOS: MAT Y MAT ESP | D27: =FECHAS!D9 -> MARTES 24 DE FEBRERO DEL 2026 | F27: =F3 -> SEM 8 LIC | G27: =G3 -> SEM 2 SEM
A28: =A4 -> Aula | B28: =B4 -> Gpo. | C28: =C4 -> Licenciatura | D28: =D4 -> Opt | E28: 0.5 | F28: 0.54166667 | G28: 0.58333333
A29: 001 | B29: 603 EAH | C29: SEMESTRAL | E29: AP17 | F29: AP17
A30: =A6 -> 002 | B30: =B6 -> 211-9 | C30: =C6 -> PSICOLOGIA | D30: =D6 -> 0 | E30: 2023 | F30: 2409 | G30: 2409
A31: 004 | D31: =D2 -> 0 | G31: =diur2!J3 -> 0
A32: =A8 -> 004 | B32: =B8 -> 401-8 | C32: =C8 -> NEGOCIOS | D32: =D8 -> 0 | E32: 2166 | F32: =diur2!I6 -> 0 | G32: =diur2!J6 -> 0
A33: =A9 -> 008 | B33: =B9 -> 511-9 | C33: =C9 -> PSICOLOGIA | D33: =D9 -> 0 | E33: 2473 | F33: =diur2!I7 -> 0 | G33: =diur2!J7 -> 0
A34: =A10 -> 102 | B34: =B10 -> 0 | C34: =C10 -> INGLES | D34: =D10 -> 0 | E34: 1433 | F34: =diur2!I8 -> 0 | G34: =diur2!J8 -> 0
A35: =A11 -> 104 | B35: =B11 -> 202 | C35: =C11 -> SEMESTRAL | D35: =D11 -> 0 | E35: AP17 | F35: AP17 | G35: =diur2!J9 -> 0
A36: 204 | B36: 101-8 | C36: =C13 -> CIVIL
A37: 206 | B37: 701-8 | C37: =C13 -> CIVIL
A38: 210 | B38: 401-8 | C38: =C14 -> CIVIL | E38: 2231
A39: 301 | B39: 601 FMQB | C39: SEMESTRAL | E39: P440 | F39: P347
A40: =A16 -> 302 | B40: =B16 -> 602 FMQB | C40: =C16 -> SEMESTRAL | E40: P433 | F40: AP38 | G40: =diur2!J12 -> 0
A41: =A17 -> 303 | B41: =B17 -> 402 | C41: =C17 -> SEMESTRAL | E41: AP5 | F41: P440 | G41: =diur2!J13 -> 0
A42: =A18 -> 304 | B42: =B18 -> 201 | C42: =C18 -> SEMESTRAL | D42: =D13 -> 0 | E42: AP36 | F42: AP36 | G42: =diur2!J14 -> 0
A43: =A19 -> 305 | B43: =B19 -> 403 | C43: =C19 -> SEMESTRAL | D43: =D16 -> 0 | E43: AP39 | F43: AP5 | G43: =diur2!J16 -> 0
...

Sheet FECHAS
D8: LUNES 23 DE FEBRERO DEL 2026 | G8: SEM 8 LIC | H8: SEM 2 SEM
D9: MARTES 24 DE FEBRERO DEL 2026
D10: MIERCOLES 25 DE FEBRERO DEL 2026
D11: JUEVES 26 DE FEBRERO DEL 2026
D12: VIERNES 27 DE FEBRERO DEL 2026
